Workbook

Sheet Sheet1
A1: FORM-3B [See Rule 61(5)]
M2: Year | O2: =Sheet2!Q4 -> 2018-19
M3: Month | O3: =Sheet2!Q5 -> April
A5: 1. | B5: GSTIN | C5: =Sheet2!D7 -> 0 | D5: =Sheet2!E7 -> 0 | E5: =Sheet2!F7 -> 0 | F5: =Sheet2!G7 -> 0 | G5: =Sheet2!H7 -> 0 | H5: =Sheet2!I7 -> 0 | I5: =Sheet2!J7 -> 0 | J5: =Sheet2!K7 -> 0 | ... Q5: =Sheet2!R7 -> 0
A6: 2. | B6: Legal Name | C6: =Sheet2!D8 -> 0
A8: 3.1 | B8: Details of outward supplies and inward supplies liable to reverse charge
A9: Nature of Supplies | C9: Taxable Value | F9: Integrated Tax | I9: Central Tax | L9: State/UT Tax | O9: Cess
A10: 1 | C10: 2 | F10: 3 | I10: 4 | L10: 5 | O10: 6
A11: (a) Outward taxable supplies (other than zero rated, nil rated and exempted) | C11: =Sheet2!D14 -> 0 | F11: =Sheet2!G14 -> 0 | I11: =Sheet2!J14 -> 0 | L11: =Sheet2!M14 -> 0 | O11: =Sheet2!P14 -> 0
A12: (b) Outward taxable supplies (zero rated) | C12: =Sheet2!D15 -> 0 | F12: =Sheet2!G15 -> 0 | I12: =Sheet2!J15 -> 0 | L12: =Sheet2!M15 -> 0 | O12: =Sheet2!P15 -> 0
A13: (c) Other outward supplies (nil rated and exempted) | C13: =Sheet2!D16 -> 0 | F13: =Sheet2!G16 -> 0 | I13: =Sheet2!J16 -> 0 | L13: =Sheet2!M16 -> 0 | O13: =Sheet2!P16 -> 0
A14: (d) Inward supplies liable to reverse charge (other than those covered in 3.1.1) | C14: =Sheet2!D17 -> 0 | F14: =Sheet2!G17 -> 0 | I14: =Sheet2!J17 -> 0 | L14: =Sheet2!M17 -> 0 | O14: =Sheet2!P17 -> 0
A15: (e) Non-GST outward supplies | C15: =Sheet2!D18 -> 0 | F15: =Sheet2!G18 -> 0 | I15: =Sheet2!J18 -> 0 | L15: =Sheet2!M18 -> 0 | O15: =Sheet2!P18 -> 0
A16: Total | C16: =+SUM(C11:E15) -> 0 | F16: =+SUM(F11:H12,F14) -> 0 | I16: =+SUM(I11,I14) -> 0 | L16: =+SUM(L11,L14) -> 0 | O16: =+SUM(O11:Q12,O14) -> 0
A18: 3.1.1 | B18: Details of supplies notified under sub-section (5) of section 9 of the Central Goods and Services Tax Act, 2017 and corresponding provisions in Integrated Goods and Services Tax/Union Territory Goods and Services Tax/State Goods and Services Tax Acts
A19: Nature of Supplies | C19: Taxable Value | F19: Integrated Tax | I19: Central Tax | L19: State/UT Tax | O19: Cess
A20: 1 | C20: 2 | F20: 3 | I20: 4 | L20: 5 | O20: 6
A21: (i) Taxable supplies on which electronic commerce operator pays tax under sub-section (5) of section 9 [to be furnished by the electronic commerce operator]
A22: (ii) Taxable supplies made by the registered person through electronic commerce operator, on which electronic commerce operator is required to pay tax under sub-section (5) of section 9 [to be furnished by person making supplies through electronic commerce operator] | C22: =Sheet2!D19 -> 0 | F22: =Sheet2!G19 -> 0 | I22: =Sheet2!J19 -> 0 | L22: =Sheet2!M19 -> 0 | O22: =Sheet2!P19 -> 0
A24: 3.2 | B24: Of the supplies shown in 3.1(a) and 3.1.1 above, details of inter-state supplies made to unregistered persons, composition taxable persons and UIN holders
A25: Particulars | F25: Place of Supply | J25: Taxable Value | N25: Integrated Tax
A26: 1 | F26: 2 | J26: 3 | N26: 4
A27: Supplies made to Unregistered Persons
A28: Supplies made to Unregistered Persons
A29: Supplies made to Unregistered Persons
A30: Supplies made to Unregistered Persons
A31: Supplies made to Unregistered Persons
A32: Supplies made to Unregistered Persons
A33: Supplies made to Unregistered Persons
A34: Supplies made to Unregistered Persons
A35: Supplies made to Unregistered Persons
A36: Supplies made to Unregistered Persons
A37: Supplies made to Unregistered Persons
A38: Supplies made to Unregistered Persons
... A57: Supplies made to UIN Holders
A58: 4. | B58: Eligible Input Tax Credit
A59: Details | F59: Integrated Tax | I59: Central Tax | L59: State/UT Tax | O59: Cess
A60: 1 | F60: 2 | I60: 3 | L60: 4 | O60: 5
A61: (A) ITC Available (whether in full or in part)
A62: (1) Import of goods | F62: =Sheet2!D45 -> 0 | I62: =Sheet2!H45 -> 0 | L62: =Sheet2!L45 -> 0 | O62: =Sheet2!P45 -> 0
...

Sheet Sheet2
B1: Form GSTR-3B
B2: [ See Rule 61(5) ]
O4: Year | Q4: 2018-19
O5: Month | Q5: April
B7: 1 | C7: GSTIN
B8: 2 | C8: Legal name of the registered person
B10: 3.1 | C10: Detail of Outward Supplies and Inward supplies liable to reverse charges
C12: Nature of Supplies | D12: Total Taxable Value | G12: Integrated Tax | J12: Central Tax | M12: State/ UT Tax | P12: Cess
C13: 1 | D13: 2 | G13: 3 | J13: 4 | M13: 5 | P13: 6
C14: ( a) Outward taxable supplies (other than zero rated, nil rated and exempted) | G14: 0 | J14: 0 | M14: 0 | P14: 0
C15: ( b) Outward taxable supplies (zero rated) | G15: 0 | J15: 0 | M15: 0 | P15: 0
C16: ( c) Other outward supplies, (Nil rated, exempted) | G16: 0 | J16: 0 | M16: 0 | P16: 0
C17: ( d) Inward supplies (liable to reverse charge) | G17: 0 | J17: 0 | M17: 0 | P17: 0
C18: ( e) Non GST outward supplies
C19: ( f) Supplies U/S 9(5) | G19: 0 | J19: 0 | M19: 0 | P19: 0
B21: 3.2 | C21: 3.2 Of the supplies shown in 3.1 (a) above, details of inter-State supplies made to unregistered persons,
C22: composition taxable persons and UIN holders
D24: Place of Supply (State/UT) | I24: Total Taxable Value | N24: Amount of Integrated Tax
C25: 1 | D25: 2 | I25: 3 | N25: 4
C26: Supplies made to Unregistered Persons
C27: Supplies made to Unregistered Persons
C28: Supplies made to Unregistered Persons
C29: Supplies made to Unregistered Persons
C30: Supplies made to Unregistered Persons
C31: Supplies made to Unregistered Persons
C32: Supplies made to Composition Taxable Persons
C33: Supplies made to Composition Taxable Persons
C34: Supplies made to Composition Taxable Persons
C35: Supplies made to Composition Taxable Persons
C36: Supplies made to Composition Taxable Persons
C37: Supplies made to Composition Taxable Persons
C38: Supplies made to UIN Holders
C40: Opening Balance | D40: 0 | H40: 0 | L40: 0 | P40: 0
B41: 4 | C41: Eligible ITC
C42: Details | D42: Integrated Tax | H42: Central Tax | L42: State/ UT Tax | P42: Cess
C43: 1 | D43: 2 | H43: 3 | L43: 4 | P43: 5
C44: (A) ITC Available (whether in full or part)
C45: (1) Import of goods | D45: 0 | P45: 0
C46: (2) Import of services | D46: 0 | P46: 0
C47: (3) Inward supplies liable to reverse charge (other | D47: 0
...

Sheet Sale
E1: =SUBTOTAL(9,E3:E5000) -> 0 | G1: =SUBTOTAL(9,G3:G5000) -> 0 | H1: =SUBTOTAL(9,H3:H5000) -> 0 | I1: =SUBTOTAL(9,I3:I5000) -> 0 | J1: =SUBTOTAL(9,J3:J5000) -> 0
A2: Account Name | B2: GST No. | C2: Bill No. | D2: Date | E2: Taxable Value | F2: Gst Rate | G2: C.Gst | H2: S.Gst | I2: I.Gst | J2: Cess | K2: Sheet2 Col.No.

Sheet Purchase
E1: =SUBTOTAL(9,E3:E5000) -> 0 | G1: =SUBTOTAL(9,G3:G5000) -> 0 | H1: =SUBTOTAL(9,H3:H5000) -> 0 | I1: =SUBTOTAL(9,I3:I5000) -> 0 | J1: =SUBTOTAL(9,J3:J5000) -> 0
A2: Account Name | B2: GST No. | C2: Bill No. | D2: Input Date | E2: Taxable Value | F2: Gst Rate | G2: C.Gst | H2: S.Gst | I2: I.Gst | J2: Cess | K2: Sheet2 Col.No. | L2: Vch. Date

Sheet Other
E1: =SUBTOTAL(9,E3:E5000) -> 0 | G1: =SUBTOTAL(9,G3:G5000) -> 0 | H1: =SUBTOTAL(9,H3:H5000) -> 0 | I1: =SUBTOTAL(9,I3:I5000) -> 0 | J1: =SUBTOTAL(9,J3:J5000) -> 0
A2: Account Name | B2: State Name | C2: Bill No. | D2: Date | E2: Taxable Value | F2: Gst Rate | G2: C.Gst | H2: S.Gst | I2: I.Gst | J2: Cess | K2: Tax Type
