Workbook

Sheet Pur_Sale
A5: A/c Code | B5: April | C5: May | D5: June | E5: July | F5: August | G5: Sept. | H5: October | I5: Nov | J5: December | K5: January | L5: February | M5: March | N5: Total
A6: SALES
A7: REGISTERED TAXABLE WITHIN STATE | N7: =SUM(B7:M7) -> 0
A8: REGISTERED TAXABLE OUT OF STATE | N8: =SUM(B8:M8) -> 0
A9: UN-REGISTER TAXABLE WITHIN STATE | N9: =SUM(B9:M9) -> 0
A10: UN-REGISTER TAXABLE OUT OF STATE | N10: =SUM(B10:M10) -> 0
A11: TAX FREE WITHIN STATE | N11: =SUM(B11:M11) -> 0
A12: TAX FREE OUT OF STATE | N12: =SUM(B12:M12) -> 0
A13: EXPORT SALE | N13: =SUM(B13:M13) -> 0
A14: TOTAL | B14: =SUM(B7:B13) -> 0 | C14: =SUM(C7:C13) -> 0 | D14: =SUM(D7:D13) -> 0 | E14: =SUM(E7:E13) -> 0 | F14: =SUM(F7:F13) -> 0 | G14: =SUM(G7:G13) -> 0 | H14: =SUM(H7:H13) -> 0 | I14: =SUM(I7:I13) -> 0 | ... N14: =SUM(N7:N13) -> 0
A16: PURCHASE
A17: REGISTERED TAXABLE WITHIN STATE | N17: =SUM(B17:M17) -> 0
A18: REGISTERED TAXABLE OUT OF STATE | N18: =SUM(B18:M18) -> 0
A19: UN-REG TAXABLE WITHIN STATE | N19: =SUM(B19:M19) -> 0
A20: UN-REG TAXABLE OUT OF STATE | N20: =SUM(B20:M20) -> 0
A21: TAX FREE WITHIN STATE | N21: =SUM(B21:M21) -> 0
A22: TAX FREE OUT OF STATE | N22: =SUM(B22:M22) -> 0
A23: IMPORT | N23: =SUM(B23:M23) -> 0
A24: NOT ELIGIBLE FOR ITC WITHIN STATE | N24: =SUM(B24:M24) -> 0
A25: NOT ELIGIBLE FOR ITC OUT OF STATE | N25: =SUM(B25:M25) -> 0
A26: TOTAL | B26: =SUM(B17:B25) -> 0 | C26: =SUM(C17:C25) -> 0 | D26: =SUM(D17:D25) -> 0 | E26: =SUM(E17:E25) -> 0 | F26: =SUM(F17:F25) -> 0 | G26: =SUM(G17:G25) -> 0 | H26: =SUM(H17:H25) -> 0 | I26: =SUM(I17:I25) -> 0 | ... N26: =SUM(N17:N25) -> 0
A27: CGST
A28: OUTPUT TAX
A29: REGISTERED TAXABLE WITHIN STATE | N29: =SUM(B29:M29) -> 0
A30: UN-REG TAXABLE WITHIN STATE | N30: =SUM(B30:M30) -> 0
A31: EXPORT / IMPORT | N31: =SUM(B31:M31) -> 0
A32: TOTAL | B32: =SUM(B29:B31) -> 0 | C32: =SUM(C29:C31) -> 0 | D32: =SUM(D29:D31) -> 0 | E32: =SUM(E29:E31) -> 0 | F32: =SUM(F29:F31) -> 0 | G32: =SUM(G29:G31) -> 0 | H32: =SUM(H29:H31) -> 0 | I32: =SUM(I29:I31) -> 0 | ... N32: =SUM(N29:N31) -> 0
A34: INPUT TAX
A35: REGISTERED TAXABLE WITHIN STATE | N35: =SUM(B35:M35) -> 0
A36: UN-REG TAXABLE WITHIN STATE | N36: =SUM(B36:M36) -> 0
A37: EXPORT / IMPORT | N37: =SUM(B37:M37) -> 0
A38: TOTAL | B38: =SUM(B35:B37) -> 0 | C38: =SUM(C35:C37) -> 0 | D38: =SUM(D35:D37) -> 0 | E38: =SUM(E35:E37) -> 0 | F38: =SUM(F35:F37) -> 0 | G38: =SUM(G35:G37) -> 0 | H38: =SUM(H35:H37) -> 0 | I38: =SUM(I35:I37) -> 0 | ... N38: =SUM(N35:N37) -> 0
A39: NET TAX | B39: =B38-B32 -> 0 | C39: =C38-C32 -> 0 | D39: =D38-D32 -> 0 | E39: =E38-E32 -> 0 | F39: =F38-F32 -> 0 | G39: =G38-G32 -> 0 | H39: =H38-H32 -> 0 | I39: =I38-I32 -> 0 | ... N39: =N38-N32 -> 0
A40: NOT ELIGIBLE FOR ITC
A41: SGST
A42: OUTPUT TAX
A43: REGISTERED TAXABLE WITHIN STATE | N43: =SUM(B43:M43) -> 0
A44: UN-REG TAXABLE WITHIN STATE | N44: =SUM(B44:M44) -> 0
A45: EXPORT / IMPORT | N45: =SUM(B45:M45) -> 0
A46: TOTAL | B46: =SUM(B43:B45) -> 0 | C46: =SUM(C43:C45) -> 0 | D46: =SUM(D43:D45) -> 0 | E46: =SUM(E43:E45) -> 0 | F46: =SUM(F43:F45) -> 0 | G46: =SUM(G43:G45) -> 0 | H46: =SUM(H43:H45) -> 0 | I46: =SUM(I43:I45) -> 0 | ... N46: =SUM(N43:N45) -> 0
...

Sheet Debit_Credit_Note
A5: A/c Code | B5: April | C5: May | D5: June | E5: July | F5: August | G5: Sept. | H5: October | I5: Nov | J5: December | K5: January | L5: February | M5: March | N5: Total
A6: LESS SALES / CREDIT NOTE
A7: REGISTERED TAXABLE WITHIN STATE | N7: =SUM(B7:M7) -> 0
A8: REGISTERED TAXABLE OUT OF STATE | N8: =SUM(B8:M8) -> 0
A9: UN-REGISTER TAXABLE WITHIN STATE | N9: =SUM(B9:M9) -> 0
A10: UN-REGISTER TAXABLE OUT OF STATE | N10: =SUM(B10:M10) -> 0
A11: TAX FREE WITHIN STATE | N11: =SUM(B11:M11) -> 0
A12: TAX FREE OUT OF STATE | N12: =SUM(B12:M12) -> 0
A13: EXPORT SALE | N13: =SUM(B13:M13) -> 0
A14: TOTAL | B14: =SUM(B7:B13) -> 0 | C14: =SUM(C7:C13) -> 0 | D14: =SUM(D7:D13) -> 0 | E14: =SUM(E7:E13) -> 0 | F14: =SUM(F7:F13) -> 0 | G14: =SUM(G7:G13) -> 0 | H14: =SUM(H7:H13) -> 0 | I14: =SUM(I7:I13) -> 0 | ... N14: =SUM(N7:N13) -> 0
A16: LESS PURCHASE / DEBIT NOTE
A17: REGISTERED TAXABLE WITHIN STATE | N17: =SUM(B17:M17) -> 0
A18: REGISTERED TAXABLE OUT OF STATE | N18: =SUM(B18:M18) -> 0
A19: UN-REG TAXABLE WITHIN STATE | N19: =SUM(B19:M19) -> 0
A20: UN-REG TAXABLE OUT OF STATE | N20: =SUM(B20:M20) -> 0
A21: TAX FREE WITHIN STATE | N21: =SUM(B21:M21) -> 0
A22: TAX FREE OUT OF STATE | N22: =SUM(B22:M22) -> 0
A23: IMPORT | N23: =SUM(B23:M23) -> 0
A24: NOT ELIGIBLE FOR ITC WITHIN STATE | N24: =SUM(B24:M24) -> 0
A25: NOT ELIGIBLE FOR ITC OUT OF STATE | N25: =SUM(B25:M25) -> 0
A26: TOTAL | B26: =SUM(B17:B25) -> 0 | C26: =SUM(C17:C25) -> 0 | D26: =SUM(D17:D25) -> 0 | E26: =SUM(E17:E25) -> 0 | F26: =SUM(F17:F25) -> 0 | G26: =SUM(G17:G25) -> 0 | H26: =SUM(H17:H25) -> 0 | I26: =SUM(I17:I25) -> 0 | ... N26: =SUM(N17:N25) -> 0
A27: CGST
A28: OUTPUT TAX
A29: REGISTERED TAXABLE WITHIN STATE | N29: =SUM(B29:M29) -> 0
A30: UN-REG TAXABLE WITHIN STATE | N30: =SUM(B30:M30) -> 0
A31: EXPORT / IMPORT | N31: =SUM(B31:M31) -> 0
A32: TOTAL | B32: =SUM(B29:B31) -> 0 | C32: =SUM(C29:C31) -> 0 | D32: =SUM(D29:D31) -> 0 | E32: =SUM(E29:E31) -> 0 | F32: =SUM(F29:F31) -> 0 | G32: =SUM(G29:G31) -> 0 | H32: =SUM(H29:H31) -> 0 | I32: =SUM(I29:I31) -> 0 | ... N32: =SUM(N29:N31) -> 0
A34: INPUT TAX
A35: REGISTERED TAXABLE WITHIN STATE | N35: =SUM(B35:M35) -> 0
A36: UN-REG TAXABLE WITHIN STATE | N36: =SUM(B36:M36) -> 0
A37: EXPORT / IMPORT | N37: =SUM(B37:M37) -> 0
A38: TOTAL | B38: =SUM(B35:B37) -> 0 | C38: =SUM(C35:C37) -> 0 | D38: =SUM(D35:D37) -> 0 | E38: =SUM(E35:E37) -> 0 | F38: =SUM(F35:F37) -> 0 | G38: =SUM(G35:G37) -> 0 | H38: =SUM(H35:H37) -> 0 | I38: =SUM(I35:I37) -> 0 | ... N38: =SUM(N35:N37) -> 0
A39: NET TAX | B39: =B38-B32 -> 0 | C39: =C38-C32 -> 0 | D39: =D38-D32 -> 0 | E39: =E38-E32 -> 0 | F39: =F38-F32 -> 0 | G39: =G38-G32 -> 0 | H39: =H38-H32 -> 0 | I39: =I38-I32 -> 0 | ... N39: =N38-N32 -> 0
A40: NOT ELIGIBLE FOR ITC
A41: SGST
A42: OUTPUT TAX
A43: REGISTERED TAXABLE WITHIN STATE | N43: =SUM(B43:M43) -> 0
A44: UN-REG TAXABLE WITHIN STATE | N44: =SUM(B44:M44) -> 0
A45: EXPORT / IMPORT | N45: =SUM(B45:M45) -> 0
A46: TOTAL | B46: =SUM(B43:B45) -> 0 | C46: =SUM(C43:C45) -> 0 | D46: =SUM(D43:D45) -> 0 | E46: =SUM(E43:E45) -> 0 | F46: =SUM(F43:F45) -> 0 | G46: =SUM(G43:G45) -> 0 | H46: =SUM(H43:H45) -> 0 | I46: =SUM(I43:I45) -> 0 | ... N46: =SUM(N43:N45) -> 0
...

Sheet Net Pur.Sale
A5: A/c Code | B5: April | C5: May | D5: June | E5: July | F5: August | G5: Sept. | H5: October | I5: Nov | J5: December | K5: January | L5: February | M5: March | N5: Total
A6: SALES
A7: REGISTERED TAXABLE WITHIN STATE | B7: =Pur_Sale!B7+Debit_Credit_Note!B7 -> 0 | C7: =Pur_Sale!C7+Debit_Credit_Note!C7 -> 0 | D7: =Pur_Sale!D7+Debit_Credit_Note!D7 -> 0 | E7: =Pur_Sale!E7+Debit_Credit_Note!E7 -> 0 | F7: =Pur_Sale!F7+Debit_Credit_Note!F7 -> 0 | G7: =Pur_Sale!G7+Debit_Credit_Note!G7 -> 0 | H7: =Pur_Sale!H7+Debit_Credit_Note!H7 -> 0 | I7: =Pur_Sale!I7+Debit_Credit_Note!I7 -> 0 | ... M7: =Pur_Sale!M7+Debit_Credit_Note!M7 -> 0 | N7: =SUM(B7:M7) -> 0
A8: REGISTERED TAXABLE OUT OF STATE | B8: =Pur_Sale!B8+Debit_Credit_Note!B8 -> 0 | C8: =Pur_Sale!C8+Debit_Credit_Note!C8 -> 0 | D8: =Pur_Sale!D8+Debit_Credit_Note!D8 -> 0 | E8: =Pur_Sale!E8+Debit_Credit_Note!E8 -> 0 | F8: =Pur_Sale!F8+Debit_Credit_Note!F8 -> 0 | G8: =Pur_Sale!G8+Debit_Credit_Note!G8 -> 0 | H8: =Pur_Sale!H8+Debit_Credit_Note!H8 -> 0 | I8: =Pur_Sale!I8+Debit_Credit_Note!I8 -> 0 | ... M8: =Pur_Sale!M8+Debit_Credit_Note!M8 -> 0 | N8: =SUM(B8:M8) -> 0
A9: UN-REGISTER TAXABLE WITHIN STATE | B9: =Pur_Sale!B9+Debit_Credit_Note!B9 -> 0 | C9: =Pur_Sale!C9+Debit_Credit_Note!C9 -> 0 | D9: =Pur_Sale!D9+Debit_Credit_Note!D9 -> 0 | E9: =Pur_Sale!E9+Debit_Credit_Note!E9 -> 0 | F9: =Pur_Sale!F9+Debit_Credit_Note!F9 -> 0 | G9: =Pur_Sale!G9+Debit_Credit_Note!G9 -> 0 | H9: =Pur_Sale!H9+Debit_Credit_Note!H9 -> 0 | I9: =Pur_Sale!I9+Debit_Credit_Note!I9 -> 0 | ... M9: =Pur_Sale!M9+Debit_Credit_Note!M9 -> 0 | N9: =SUM(B9:M9) -> 0
A10: UN-REGISTER TAXABLE OUT OF STATE | B10: =Pur_Sale!B10+Debit_Credit_Note!B10 -> 0 | C10: =Pur_Sale!C10+Debit_Credit_Note!C10 -> 0 | D10: =Pur_Sale!D10+Debit_Credit_Note!D10 -> 0 | E10: =Pur_Sale!E10+Debit_Credit_Note!E10 -> 0 | F10: =Pur_Sale!F10+Debit_Credit_Note!F10 -> 0 | G10: =Pur_Sale!G10+Debit_Credit_Note!G10 -> 0 | H10: =Pur_Sale!H10+Debit_Credit_Note!H10 -> 0 | I10: =Pur_Sale!I10+Debit_Credit_Note!I10 -> 0 | ... M10: =Pur_Sale!M10+Debit_Credit_Note!M10 -> 0 | N10: =SUM(B10:M10) -> 0
A11: TAX FREE WITHIN STATE | B11: =Pur_Sale!B11+Debit_Credit_Note!B11 -> 0 | C11: =Pur_Sale!C11+Debit_Credit_Note!C11 -> 0 | D11: =Pur_Sale!D11+Debit_Credit_Note!D11 -> 0 | E11: =Pur_Sale!E11+Debit_Credit_Note!E11 -> 0 | F11: =Pur_Sale!F11+Debit_Credit_Note!F11 -> 0 | G11: =Pur_Sale!G11+Debit_Credit_Note!G11 -> 0 | H11: =Pur_Sale!H11+Debit_Credit_Note!H11 -> 0 | I11: =Pur_Sale!I11+Debit_Credit_Note!I11 -> 0 | ... M11: =Pur_Sale!M11+Debit_Credit_Note!M11 -> 0 | N11: =SUM(B11:M11) -> 0
A12: TAX FREE OUT OF STATE | B12: =Pur_Sale!B12+Debit_Credit_Note!B12 -> 0 | C12: =Pur_Sale!C12+Debit_Credit_Note!C12 -> 0 | D12: =Pur_Sale!D12+Debit_Credit_Note!D12 -> 0 | E12: =Pur_Sale!E12+Debit_Credit_Note!E12 -> 0 | F12: =Pur_Sale!F12+Debit_Credit_Note!F12 -> 0 | G12: =Pur_Sale!G12+Debit_Credit_Note!G12 -> 0 | H12: =Pur_Sale!H12+Debit_Credit_Note!H12 -> 0 | I12: =Pur_Sale!I12+Debit_Credit_Note!I12 -> 0 | ... M12: =Pur_Sale!M12+Debit_Credit_Note!M12 -> 0 | N12: =SUM(B12:M12) -> 0
A13: EXPORT SALE | B13: =Pur_Sale!B13+Debit_Credit_Note!B13 -> 0 | C13: =Pur_Sale!C13+Debit_Credit_Note!C13 -> 0 | D13: =Pur_Sale!D13+Debit_Credit_Note!D13 -> 0 | E13: =Pur_Sale!E13+Debit_Credit_Note!E13 -> 0 | F13: =Pur_Sale!F13+Debit_Credit_Note!F13 -> 0 | G13: =Pur_Sale!G13+Debit_Credit_Note!G13 -> 0 | H13: =Pur_Sale!H13+Debit_Credit_Note!H13 -> 0 | I13: =Pur_Sale!I13+Debit_Credit_Note!I13 -> 0 | ... M13: =Pur_Sale!M13+Debit_Credit_Note!M13 -> 0 | N13: =SUM(B13:M13) -> 0
A14: TOTAL | B14: =SUM(B7:B13) -> 0 | C14: =SUM(C7:C13) -> 0 | D14: =SUM(D7:D13) -> 0 | E14: =SUM(E7:E13) -> 0 | F14: =SUM(F7:F13) -> 0 | G14: =SUM(G7:G13) -> 0 | H14: =SUM(H7:H13) -> 0 | I14: =SUM(I7:I13) -> 0 | ... N14: =SUM(N7:N13) -> 0
A16: PURCHASE
A17: REGISTERED TAXABLE WITHIN STATE | B17: =Pur_Sale!B17+Debit_Credit_Note!B17 -> 0 | C17: =Pur_Sale!C17+Debit_Credit_Note!C17 -> 0 | D17: =Pur_Sale!D17+Debit_Credit_Note!D17 -> 0 | E17: =Pur_Sale!E17+Debit_Credit_Note!E17 -> 0 | F17: =Pur_Sale!F17+Debit_Credit_Note!F17 -> 0 | G17: =Pur_Sale!G17+Debit_Credit_Note!G17 -> 0 | H17: =Pur_Sale!H17+Debit_Credit_Note!H17 -> 0 | I17: =Pur_Sale!I17+Debit_Credit_Note!I17 -> 0 | ... M17: =Pur_Sale!M17+Debit_Credit_Note!M17 -> 0 | N17: =SUM(B17:M17) -> 0
A18: REGISTERED TAXABLE OUT OF STATE | B18: =Pur_Sale!B18+Debit_Credit_Note!B18 -> 0 | C18: =Pur_Sale!C18+Debit_Credit_Note!C18 -> 0 | D18: =Pur_Sale!D18+Debit_Credit_Note!D18 -> 0 | E18: =Pur_Sale!E18+Debit_Credit_Note!E18 -> 0 | F18: =Pur_Sale!F18+Debit_Credit_Note!F18 -> 0 | G18: =Pur_Sale!G18+Debit_Credit_Note!G18 -> 0 | H18: =Pur_Sale!H18+Debit_Credit_Note!H18 -> 0 | I18: =Pur_Sale!I18+Debit_Credit_Note!I18 -> 0 | ... M18: =Pur_Sale!M18+Debit_Credit_Note!M18 -> 0 | N18: =SUM(B18:M18) -> 0
A19: UN-REG TAXABLE WITHIN STATE | B19: =Pur_Sale!B19+Debit_Credit_Note!B19 -> 0 | C19: =Pur_Sale!C19+Debit_Credit_Note!C19 -> 0 | D19: =Pur_Sale!D19+Debit_Credit_Note!D19 -> 0 | E19: =Pur_Sale!E19+Debit_Credit_Note!E19 -> 0 | F19: =Pur_Sale!F19+Debit_Credit_Note!F19 -> 0 | G19: =Pur_Sale!G19+Debit_Credit_Note!G19 -> 0 | H19: =Pur_Sale!H19+Debit_Credit_Note!H19 -> 0 | I19: =Pur_Sale!I19+Debit_Credit_Note!I19 -> 0 | ... M19: =Pur_Sale!M19+Debit_Credit_Note!M19 -> 0 | N19: =SUM(B19:M19) -> 0
A20: UN-REG TAXABLE OUT OF STATE | B20: =Pur_Sale!B20+Debit_Credit_Note!B20 -> 0 | C20: =Pur_Sale!C20+Debit_Credit_Note!C20 -> 0 | D20: =Pur_Sale!D20+Debit_Credit_Note!D20 -> 0 | E20: =Pur_Sale!E20+Debit_Credit_Note!E20 -> 0 | F20: =Pur_Sale!F20+Debit_Credit_Note!F20 -> 0 | G20: =Pur_Sale!G20+Debit_Credit_Note!G20 -> 0 | H20: =Pur_Sale!H20+Debit_Credit_Note!H20 -> 0 | I20: =Pur_Sale!I20+Debit_Credit_Note!I20 -> 0 | ... M20: =Pur_Sale!M20+Debit_Credit_Note!M20 -> 0 | N20: =SUM(B20:M20) -> 0
A21: TAX FREE WITHIN STATE | B21: =Pur_Sale!B21+Debit_Credit_Note!B21 -> 0 | C21: =Pur_Sale!C21+Debit_Credit_Note!C21 -> 0 | D21: =Pur_Sale!D21+Debit_Credit_Note!D21 -> 0 | E21: =Pur_Sale!E21+Debit_Credit_Note!E21 -> 0 | F21: =Pur_Sale!F21+Debit_Credit_Note!F21 -> 0 | G21: =Pur_Sale!G21+Debit_Credit_Note!G21 -> 0 | H21: =Pur_Sale!H21+Debit_Credit_Note!H21 -> 0 | I21: =Pur_Sale!I21+Debit_Credit_Note!I21 -> 0 | ... M21: =Pur_Sale!M21+Debit_Credit_Note!M21 -> 0 | N21: =SUM(B21:M21) -> 0
A22: TAX FREE OUT OF STATE | B22: =Pur_Sale!B22+Debit_Credit_Note!B22 -> 0 | C22: =Pur_Sale!C22+Debit_Credit_Note!C22 -> 0 | D22: =Pur_Sale!D22+Debit_Credit_Note!D22 -> 0 | E22: =Pur_Sale!E22+Debit_Credit_Note!E22 -> 0 | F22: =Pur_Sale!F22+Debit_Credit_Note!F22 -> 0 | G22: =Pur_Sale!G22+Debit_Credit_Note!G22 -> 0 | H22: =Pur_Sale!H22+Debit_Credit_Note!H22 -> 0 | I22: =Pur_Sale!I22+Debit_Credit_Note!I22 -> 0 | ... M22: =Pur_Sale!M22+Debit_Credit_Note!M22 -> 0 | N22: =SUM(B22:M22) -> 0
A23: IMPORT | B23: =Pur_Sale!B23+Debit_Credit_Note!B23 -> 0 | C23: =Pur_Sale!C23+Debit_Credit_Note!C23 -> 0 | D23: =Pur_Sale!D23+Debit_Credit_Note!D23 -> 0 | E23: =Pur_Sale!E23+Debit_Credit_Note!E23 -> 0 | F23: =Pur_Sale!F23+Debit_Credit_Note!F23 -> 0 | G23: =Pur_Sale!G23+Debit_Credit_Note!G23 -> 0 | H23: =Pur_Sale!H23+Debit_Credit_Note!H23 -> 0 | I23: =Pur_Sale!I23+Debit_Credit_Note!I23 -> 0 | ... M23: =Pur_Sale!M23+Debit_Credit_Note!M23 -> 0 | N23: =SUM(B23:M23) -> 0
A24: NOT ELIGIBLE FOR ITC WITHIN STATE | B24: =Pur_Sale!B24+Debit_Credit_Note!B24 -> 0 | C24: =Pur_Sale!C24+Debit_Credit_Note!C24 -> 0 | D24: =Pur_Sale!D24+Debit_Credit_Note!D24 -> 0 | E24: =Pur_Sale!E24+Debit_Credit_Note!E24 -> 0 | F24: =Pur_Sale!F24+Debit_Credit_Note!F24 -> 0 | G24: =Pur_Sale!G24+Debit_Credit_Note!G24 -> 0 | H24: =Pur_Sale!H24+Debit_Credit_Note!H24 -> 0 | I24: =Pur_Sale!I24+Debit_Credit_Note!I24 -> 0 | ... M24: =Pur_Sale!M24+Debit_Credit_Note!M24 -> 0 | N24: =SUM(B24:M24) -> 0
A25: NOT ELIGIBLE FOR ITC OUT OF STATE | B25: =Pur_Sale!B25+Debit_Credit_Note!B25 -> 0 | C25: =Pur_Sale!C25+Debit_Credit_Note!C25 -> 0 | D25: =Pur_Sale!D25+Debit_Credit_Note!D25 -> 0 | E25: =Pur_Sale!E25+Debit_Credit_Note!E25 -> 0 | F25: =Pur_Sale!F25+Debit_Credit_Note!F25 -> 0 | G25: =Pur_Sale!G25+Debit_Credit_Note!G25 -> 0 | H25: =Pur_Sale!H25+Debit_Credit_Note!H25 -> 0 | I25: =Pur_Sale!I25+Debit_Credit_Note!I25 -> 0 | ... M25: =Pur_Sale!M25+Debit_Credit_Note!M25 -> 0 | N25: =SUM(B25:M25) -> 0
A26: TOTAL | B26: =SUM(B17:B25) -> 0 | C26: =SUM(C17:C25) -> 0 | D26: =SUM(D17:D25) -> 0 | E26: =SUM(E17:E25) -> 0 | F26: =SUM(F17:F25) -> 0 | G26: =SUM(G17:G25) -> 0 | H26: =SUM(H17:H25) -> 0 | I26: =SUM(I17:I25) -> 0 | ... N26: =SUM(N17:N25) -> 0
A27: CGST
A28: OUTPUT TAX | B28: =Pur_Sale!B28+Debit_Credit_Note!B28 -> 0 | C28: =Pur_Sale!C28+Debit_Credit_Note!C28 -> 0 | D28: =Pur_Sale!D28+Debit_Credit_Note!D28 -> 0 | E28: =Pur_Sale!E28+Debit_Credit_Note!E28 -> 0 | F28: =Pur_Sale!F28+Debit_Credit_Note!F28 -> 0 | G28: =Pur_Sale!G28+Debit_Credit_Note!G28 -> 0 | H28: =Pur_Sale!H28+Debit_Credit_Note!H28 -> 0 | I28: =Pur_Sale!I28+Debit_Credit_Note!I28 -> 0 | ... M28: =Pur_Sale!M28+Debit_Credit_Note!M28 -> 0
A29: REGISTERED TAXABLE WITHIN STATE | B29: =Pur_Sale!B29+Debit_Credit_Note!B29 -> 0 | C29: =Pur_Sale!C29+Debit_Credit_Note!C29 -> 0 | D29: =Pur_Sale!D29+Debit_Credit_Note!D29 -> 0 | E29: =Pur_Sale!E29+Debit_Credit_Note!E29 -> 0 | F29: =Pur_Sale!F29+Debit_Credit_Note!F29 -> 0 | G29: =Pur_Sale!G29+Debit_Credit_Note!G29 -> 0 | H29: =Pur_Sale!H29+Debit_Credit_Note!H29 -> 0 | I29: =Pur_Sale!I29+Debit_Credit_Note!I29 -> 0 | ... M29: =Pur_Sale!M29+Debit_Credit_Note!M29 -> 0 | N29: =SUM(B29:M29) -> 0
A30: UN-REG TAXABLE WITHIN STATE | B30: =Pur_Sale!B30+Debit_Credit_Note!B30 -> 0 | C30: =Pur_Sale!C30+Debit_Credit_Note!C30 -> 0 | D30: =Pur_Sale!D30+Debit_Credit_Note!D30 -> 0 | E30: =Pur_Sale!E30+Debit_Credit_Note!E30 -> 0 | F30: =Pur_Sale!F30+Debit_Credit_Note!F30 -> 0 | G30: =Pur_Sale!G30+Debit_Credit_Note!G30 -> 0 | H30: =Pur_Sale!H30+Debit_Credit_Note!H30 -> 0 | I30: =Pur_Sale!I30+Debit_Credit_Note!I30 -> 0 | ... M30: =Pur_Sale!M30+Debit_Credit_Note!M30 -> 0 | N30: =SUM(B30:M30) -> 0
A31: EXPORT / IMPORT | B31: =Pur_Sale!B31+Debit_Credit_Note!B31 -> 0 | C31: =Pur_Sale!C31+Debit_Credit_Note!C31 -> 0 | D31: =Pur_Sale!D31+Debit_Credit_Note!D31 -> 0 | E31: =Pur_Sale!E31+Debit_Credit_Note!E31 -> 0 | F31: =Pur_Sale!F31+Debit_Credit_Note!F31 -> 0 | G31: =Pur_Sale!G31+Debit_Credit_Note!G31 -> 0 | H31: =Pur_Sale!H31+Debit_Credit_Note!H31 -> 0 | I31: =Pur_Sale!I31+Debit_Credit_Note!I31 -> 0 | ... M31: =Pur_Sale!M31+Debit_Credit_Note!M31 -> 0 | N31: =SUM(B31:M31) -> 0
A32: TOTAL | B32: =SUM(B29:B31) -> 0 | C32: =SUM(C29:C31) -> 0 | D32: =SUM(D29:D31) -> 0 | E32: =SUM(E29:E31) -> 0 | F32: =SUM(F29:F31) -> 0 | G32: =SUM(G29:G31) -> 0 | H32: =SUM(H29:H31) -> 0 | I32: =SUM(I29:I31) -> 0 | ... N32: =SUM(N29:N31) -> 0
A34: INPUT TAX | B34: =Pur_Sale!B34+Debit_Credit_Note!B34 -> 0 | C34: =Pur_Sale!C34+Debit_Credit_Note!C34 -> 0 | D34: =Pur_Sale!D34+Debit_Credit_Note!D34 -> 0 | E34: =Pur_Sale!E34+Debit_Credit_Note!E34 -> 0 | F34: =Pur_Sale!F34+Debit_Credit_Note!F34 -> 0 | G34: =Pur_Sale!G34+Debit_Credit_Note!G34 -> 0 | H34: =Pur_Sale!H34+Debit_Credit_Note!H34 -> 0 | I34: =Pur_Sale!I34+Debit_Credit_Note!I34 -> 0 | ... M34: =Pur_Sale!M34+Debit_Credit_Note!M34 -> 0
A35: REGISTERED TAXABLE WITHIN STATE | B35: =Pur_Sale!B35+Debit_Credit_Note!B35 -> 0 | C35: =Pur_Sale!C35+Debit_Credit_Note!C35 -> 0 | D35: =Pur_Sale!D35+Debit_Credit_Note!D35 -> 0 | E35: =Pur_Sale!E35+Debit_Credit_Note!E35 -> 0 | F35: =Pur_Sale!F35+Debit_Credit_Note!F35 -> 0 | G35: =Pur_Sale!G35+Debit_Credit_Note!G35 -> 0 | H35: =Pur_Sale!H35+Debit_Credit_Note!H35 -> 0 | I35: =Pur_Sale!I35+Debit_Credit_Note!I35 -> 0 | ... M35: =Pur_Sale!M35+Debit_Credit_Note!M35 -> 0 | N35: =SUM(B35:M35) -> 0
A36: UN-REG TAXABLE WITHIN STATE | B36: =Pur_Sale!B36+Debit_Credit_Note!B36 -> 0 | C36: =Pur_Sale!C36+Debit_Credit_Note!C36 -> 0 | D36: =Pur_Sale!D36+Debit_Credit_Note!D36 -> 0 | E36: =Pur_Sale!E36+Debit_Credit_Note!E36 -> 0 | F36: =Pur_Sale!F36+Debit_Credit_Note!F36 -> 0 | G36: =Pur_Sale!G36+Debit_Credit_Note!G36 -> 0 | H36: =Pur_Sale!H36+Debit_Credit_Note!H36 -> 0 | I36: =Pur_Sale!I36+Debit_Credit_Note!I36 -> 0 | ... M36: =Pur_Sale!M36+Debit_Credit_Note!M36 -> 0 | N36: =SUM(B36:M36) -> 0
A37: EXPORT / IMPORT | B37: =Pur_Sale!B37+Debit_Credit_Note!B37 -> 0 | C37: =Pur_Sale!C37+Debit_Credit_Note!C37 -> 0 | D37: =Pur_Sale!D37+Debit_Credit_Note!D37 -> 0 | E37: =Pur_Sale!E37+Debit_Credit_Note!E37 -> 0 | F37: =Pur_Sale!F37+Debit_Credit_Note!F37 -> 0 | G37: =Pur_Sale!G37+Debit_Credit_Note!G37 -> 0 | H37: =Pur_Sale!H37+Debit_Credit_Note!H37 -> 0 | I37: =Pur_Sale!I37+Debit_Credit_Note!I37 -> 0 | ... M37: =Pur_Sale!M37+Debit_Credit_Note!M37 -> 0 | N37: =SUM(B37:M37) -> 0
A38: TOTAL | B38: =Pur_Sale!B38+Debit_Credit_Note!B38 -> 0 | C38: =Pur_Sale!C38+Debit_Credit_Note!C38 -> 0 | D38: =Pur_Sale!D38+Debit_Credit_Note!D38 -> 0 | E38: =Pur_Sale!E38+Debit_Credit_Note!E38 -> 0 | F38: =Pur_Sale!F38+Debit_Credit_Note!F38 -> 0 | G38: =Pur_Sale!G38+Debit_Credit_Note!G38 -> 0 | H38: =Pur_Sale!H38+Debit_Credit_Note!H38 -> 0 | I38: =Pur_Sale!I38+Debit_Credit_Note!I38 -> 0 | ... M38: =Pur_Sale!M38+Debit_Credit_Note!M38 -> 0 | N38: =SUM(N35:N37) -> 0
A39: NET TAX | B39: =B38-B32 -> 0 | C39: =C38-C32 -> 0 | D39: =D38-D32 -> 0 | E39: =E38-E32 -> 0 | F39: =F38-F32 -> 0 | G39: =G38-G32 -> 0 | H39: =H38-H32 -> 0 | I39: =I38-I32 -> 0 | ... N39: =N38-N32 -> 0
A40: NOT ELIGIBLE FOR ITC
A41: SGST
A42: OUTPUT TAX | B42: =Pur_Sale!B42+Debit_Credit_Note!B42 -> 0 | C42: =Pur_Sale!C42+Debit_Credit_Note!C42 -> 0 | D42: =Pur_Sale!D42+Debit_Credit_Note!D42 -> 0 | E42: =Pur_Sale!E42+Debit_Credit_Note!E42 -> 0 | F42: =Pur_Sale!F42+Debit_Credit_Note!F42 -> 0 | G42: =Pur_Sale!G42+Debit_Credit_Note!G42 -> 0 | H42: =Pur_Sale!H42+Debit_Credit_Note!H42 -> 0 | I42: =Pur_Sale!I42+Debit_Credit_Note!I42 -> 0 | ... M42: =Pur_Sale!M42+Debit_Credit_Note!M42 -> 0
A43: REGISTERED TAXABLE WITHIN STATE | B43: =Pur_Sale!B43+Debit_Credit_Note!B43 -> 0 | C43: =Pur_Sale!C43+Debit_Credit_Note!C43 -> 0 | D43: =Pur_Sale!D43+Debit_Credit_Note!D43 -> 0 | E43: =Pur_Sale!E43+Debit_Credit_Note!E43 -> 0 | F43: =Pur_Sale!F43+Debit_Credit_Note!F43 -> 0 | G43: =Pur_Sale!G43+Debit_Credit_Note!G43 -> 0 | H43: =Pur_Sale!H43+Debit_Credit_Note!H43 -> 0 | I43: =Pur_Sale!I43+Debit_Credit_Note!I43 -> 0 | ... M43: =Pur_Sale!M43+Debit_Credit_Note!M43 -> 0 | N43: =SUM(B43:M43) -> 0
A44: UN-REG TAXABLE WITHIN STATE | B44: =Pur_Sale!B44+Debit_Credit_Note!B44 -> 0 | C44: =Pur_Sale!C44+Debit_Credit_Note!C44 -> 0 | D44: =Pur_Sale!D44+Debit_Credit_Note!D44 -> 0 | E44: =Pur_Sale!E44+Debit_Credit_Note!E44 -> 0 | F44: =Pur_Sale!F44+Debit_Credit_Note!F44 -> 0 | G44: =Pur_Sale!G44+Debit_Credit_Note!G44 -> 0 | H44: =Pur_Sale!H44+Debit_Credit_Note!H44 -> 0 | I44: =Pur_Sale!I44+Debit_Credit_Note!I44 -> 0 | ... M44: =Pur_Sale!M44+Debit_Credit_Note!M44 -> 0 | N44: =SUM(B44:M44) -> 0
A45: EXPORT / IMPORT | B45: =Pur_Sale!B45+Debit_Credit_Note!B45 -> 0 | C45: =Pur_Sale!C45+Debit_Credit_Note!C45 -> 0 | D45: =Pur_Sale!D45+Debit_Credit_Note!D45 -> 0 | E45: =Pur_Sale!E45+Debit_Credit_Note!E45 -> 0 | F45: =Pur_Sale!F45+Debit_Credit_Note!F45 -> 0 | G45: =Pur_Sale!G45+Debit_Credit_Note!G45 -> 0 | H45: =Pur_Sale!H45+Debit_Credit_Note!H45 -> 0 | I45: =Pur_Sale!I45+Debit_Credit_Note!I45 -> 0 | ... M45: =Pur_Sale!M45+Debit_Credit_Note!M45 -> 0 | N45: =SUM(B45:M45) -> 0
A46: TOTAL | B46: =SUM(B43:B45) -> 0 | C46: =SUM(C43:C45) -> 0 | D46: =SUM(D43:D45) -> 0 | E46: =SUM(E43:E45) -> 0 | F46: =SUM(F43:F45) -> 0 | G46: =SUM(G43:G45) -> 0 | H46: =SUM(H43:H45) -> 0 | I46: =SUM(I43:I45) -> 0 | ... N46: =SUM(N43:N45) -> 0
...
